Workbook

Sheet Viral_protein_interaction_with_
B1: Ensembl_ID | C1: Regulation | D1: PBS_1 | E1: PBS_2 | F1: PBS_3 | G1: PBS_4 | H1: PBS_5 | I1: PBS_6 | J1: CVB3_1 | K1: CVB3_2 | L1: CVB3_3 | M1: CVB3_4 | N1: CVB3_5 | O1: CVB3_6 | P1: Adj P | Q1: Log2FC
A2: Ccl3 | B2: ENSMUSG00000000982 | C2: Up | D2: 5.09971 | E2: 4.86651 | F2: 5.13969 | G2: 4.81819 | H2: 4.68009 | I2: 4.7085 | J2: 7.62399 | K2: 6.33273 | L2: 6.39305 | M2: 6.62982 | N2: 6.72262 | O2: 7.52236 | P2: =_xlfn.XLOOKUP($A2, DEG!$B:$B, DEG!$E:$E, "not sig") -> 6.0734935e-05 | Q2: =IFERROR(VALUE(_xlfn.XLOOKUP($A2, DEG!$B:$B, DEG!$D:$D)), "") -> 1.9853133
A3: Ccl24 | B3: ENSMUSG00000004814 | C3: None | D3: 6.11657 | E3: 5.75853 | F3: 5.74079 | G3: 6.26951 | H3: 6.12224 | I3: 5.9818 | J3: 5.69798 | K3: 5.35846 | L3: 5.56609 | M3: 5.8922 | N3: 5.94534 | O3: 5.80858 | P3: =_xlfn.XLOOKUP($A3, DEG!$B:$B, DEG!$E:$E, "not sig") -> not sig | Q3: =IFERROR(VALUE(_xlfn.XLOOKUP($A3, DEG!$B:$B, DEG!$D:$D)), "")
A4: Tnfsf14 | B4: ENSMUSG00000005824 | C4: None | D4: 4.40678 | E4: 4.36813 | F4: 4.44538 | G4: 4.61647 | H4: 4.49555 | I4: 4.58191 | J4: 4.2648 | K4: 4.57567 | L4: 4.48364 | M4: 4.45963 | N4: 4.48425 | O4: 4.45963 | P4: =_xlfn.XLOOKUP($A4, DEG!$B:$B, DEG!$E:$E, "not sig") -> not sig | Q4: =IFERROR(VALUE(_xlfn.XLOOKUP($A4, DEG!$B:$B, DEG!$D:$D)), "")
A5: Ccl8 | B5: ENSMUSG00000009185 | C5: Up | D5: 4.1069 | E5: 4.15382 | F5: 4.60538 | G5: 4.58434 | H5: 4.407 | I5: 3.89722 | J5: 8.23425 | K5: 7.10983 | L5: 6.64488 | M5: 7.8129 | N5: 7.07789 | O5: 8.69405 | P5: =_xlfn.XLOOKUP($A5, DEG!$B:$B, DEG!$E:$E, "not sig") -> 1.5363127e-05 | Q5: =IFERROR(VALUE(_xlfn.XLOOKUP($A5, DEG!$B:$B, DEG!$D:$D)), "") -> 3.30319
A6: Csf1 | B6: ENSMUSG00000014599 | C6: None | D6: 7.70747 | E6: 7.63453 | F6: 7.63413 | G6: 7.7924 | H6: 7.68622 | I6: 7.81939 | J6: 7.80106 | K6: 7.66437 | L6: 7.71308 | M6: 7.66425 | N6: 7.96651 | O6: 7.90611 | P6: =_xlfn.XLOOKUP($A6, DEG!$B:$B, DEG!$E:$E, "not sig") -> not sig | Q6: =IFERROR(VALUE(_xlfn.XLOOKUP($A6, DEG!$B:$B, DEG!$D:$D)), "")
A7: Il19 | B7: ENSMUSG00000016524 | C7: None | D7: 4.18682 | E7: 4.25466 | F7: 4.24261 | G7: 4.43081 | H7: 4.28023 | I7: 4.31946 | J7: 4.23596 | K7: 4.20393 | L7: 4.28735 | M7: 4.20641 | N7: 4.0013 | O7: 4.15344 | P7: =_xlfn.XLOOKUP($A7, DEG!$B:$B, DEG!$E:$E, "not sig") -> not sig | Q7: =IFERROR(VALUE(_xlfn.XLOOKUP($A7, DEG!$B:$B, DEG!$D:$D)), "")
A8: Il10 | B8: ENSMUSG00000016529 | C8: None | D8: 3.1435 | E8: 3.21832 | F8: 3.26291 | G8: 3.14725 | H8: 3.05925 | I8: 3.37881 | J8: 3.92309 | K8: 3.08029 | L8: 3.33302 | M8: 3.49058 | N8: 3.25752 | O8: 3.59753 | P8: =_xlfn.XLOOKUP($A8, DEG!$B:$B, DEG!$E:$E, "not sig") -> not sig | Q8: =IFERROR(VALUE(_xlfn.XLOOKUP($A8, DEG!$B:$B, DEG!$D:$D)), "")
A9: Ccl6 | B9: ENSMUSG00000018927 | C9: None | D9: 8.4126 | E9: 8.43898 | F9: 8.46196 | G9: 8.63019 | H9: 8.66165 | I9: 8.3644 | J9: 8.91447 | K9: 8.74983 | L9: 8.50642 | M9: 9.21445 | N9: 9.13232 | O9: 9.19488 | P9: =_xlfn.XLOOKUP($A9, DEG!$B:$B, DEG!$E:$E, "not sig") -> not sig | Q9: =IFERROR(VALUE(_xlfn.XLOOKUP($A9, DEG!$B:$B, DEG!$D:$D)), "")
A10: Ccl4 | B10: ENSMUSG00000018930 | C10: None | D10: 5.34644 | E10: 5.30537 | F10: 5.21186 | G10: 5.36488 | H10: 5.23924 | I10: 5.43184 | J10: 5.77744 | K10: 5.39825 | L10: 5.37496 | M10: 5.45609 | N10: 5.46604 | O10: 6.11516 | P10: =_xlfn.XLOOKUP($A10, DEG!$B:$B, DEG!$E:$E, "not sig") -> not sig | Q10: =IFERROR(VALUE(_xlfn.XLOOKUP($A10, DEG!$B:$B, DEG!$D:$D)), "")
A11: Ccl9 | B11: ENSMUSG00000019122 | C11: None | D11: 7.37593 | E11: 7.21099 | F11: 7.1306 | G11: 7.75521 | H11: 7.50784 | I11: 7.34308 | J11: 7.8474 | K11: 7.62954 | L11: 7.41897 | M11: 8.19393 | N11: 7.86411 | O11: 8.14466 | P11: =_xlfn.XLOOKUP($A11, DEG!$B:$B, DEG!$E:$E, "not sig") -> not sig | Q11: =IFERROR(VALUE(_xlfn.XLOOKUP($A11, DEG!$B:$B, DEG!$D:$D)), "")
A12: Il20ra | B12: ENSMUSG00000020007 | C12: None | D12: 3.52633 | E12: 3.39744 | F12: 3.79873 | G12: 4.11557 | H12: 3.87347 | I12: 3.77622 | J12: 3.8214 | K12: 3.50644 | L12: 4.0225 | M12: 3.6998 | N12: 3.61727 | O12: 3.69079 | P12: =_xlfn.XLOOKUP($A12, DEG!$B:$B, DEG!$E:$E, "not sig") -> not sig | Q12: =IFERROR(VALUE(_xlfn.XLOOKUP($A12, DEG!$B:$B, DEG!$D:$D)), "")
A13: Ccl11 | B13: ENSMUSG00000020676 | C13: None | D13: 6.04193 | E13: 5.97543 | F13: 5.88127 | G13: 6.18199 | H13: 5.75398 | I13: 5.99536 | J13: 6.34345 | K13: 6.00412 | L13: 5.9456 | M13: 6.43969 | N13: 6.68915 | O13: 6.52484 | P13: =_xlfn.XLOOKUP($A13, DEG!$B:$B, DEG!$E:$E, "not sig") -> not sig | Q13: =IFERROR(VALUE(_xlfn.XLOOKUP($A13, DEG!$B:$B, DEG!$D:$D)), "")
... A80: Ackr4 | B80: ENSMUSG00000079355 | C80: None | D80: 6.61103 | E80: 6.5985 | F80: 6.72919 | G80: 6.8467 | H80: 6.49936 | I80: 6.28019 | J80: 6.55058 | K80: 6.52374 | L80: 6.53909 | M80: 6.83129 | N80: 6.33814 | O80: 6.64551 | P80: =_xlfn.XLOOKUP($A80, DEG!$B:$B, DEG!$E:$E, "not sig") -> not sig | Q80: =IFERROR(VALUE(_xlfn.XLOOKUP($A80, DEG!$B:$B, DEG!$D:$D)), "")

Sheet DEG
A1: ensembl_ID | B1: symbol | C1: entrezgene_id | D1: log2FC | E1: Adjusted_P_value | F1: description
A2: ENSMUSG00000025498 | B2: Irf7 | C2: 54123 | D2: 3.6411017 | E2: 4.1044875e-07 | F2: Interferon regulatory factor 7
A3: ENSMUSG00000059089 | B3: Fcgr4 | C3: 246256 | D3: 3.3842583 | E3: 2.112292e-05 | F3: Fc receptor, IgG, low affinity IV
A4: ENSMUSG00000054072 | B4: Iigp1 | C4: 60440 | D4: 3.37845 | E4: 1.4578969e-05 | F4: Interferon inducible GTPase 1
A5: ENSMUSG00000009185 | B5: Ccl8 | C5: 20307 | D5: 3.30319 | E5: 1.5363127e-05 | F5: C-C motif chemokine ligand 8
A6: ENSMUSG00000068606 | B6: Gm4841 | C6: 225594 | D6: 3.2690183 | E6: 1.527808e-05 | F6: Predicted gene 4841
A7: ENSMUSG00000090231 | B7: Cfb | C7: 14962 | D7: 3.268505 | E7: 1.5363127e-05 | F7: Complement factor B
A8: ENSMUSG00000046879 | B8: Irgm1 | C8: 15944 | D8: 3.2185433 | E8: 8.7500439e-06 | F8: Immunity-related GTPase family M member 1
A9: ENSMUSG00000028459 | B9: Cd72 | C9: 12517 | D9: 3.0289567 | E9: 1.5363127e-05 | F9: CD72 antigen
A10: ENSMUSG00000049103 | B10: Ccr2 | C10: 12772 | D10: 3.0004383 | E10: 1.527808e-05 | F10: C-C motif chemokine receptor 2
A11: ENSMUSG00000002033 | B11: Cd3g | C11: 12502 | D11: 2.9552983 | E11: 1.5363127e-05 | F11: CD3 antigen, gamma polypeptide
A12: ENSMUSG00000024675 | B12: Ms4a4c | C12: 64380 | D12: 2.86917 | E12: 1.5710531e-05 | F12: Membrane-spanning 4-domains, subfamily A, member 4C
A13: ENSMUSG00000029322 | B13: Plac8 | C13: 231507 | D13: 2.7490317 | E13: 4.9213974e-05 | F13: Placenta-specific 8
... A67: ENSMUSG00000021886 | B67: Gpr65 | C67: 14744 | D67: 1.7728983 | E67: 0.00014399829 | F67: G-protein coupled receptor 65
A68: ENSMUSG00000101628 | B68: Gm28177 | C68: NA | D68: 1.74224 | E68: 1.5363127e-05 | F68: Predicted gene 28177
A69: ENSMUSG00000036594 | B69: H2-Aa | C69: 14960 | D69: 1.738215 | E69: 2.2759663e-05 | F69: Histocompatibility 2, class II antigen A, alpha
A70: ENSMUSG00000030107 | B70: Usp18 | C70: 24110 | D70: 1.7341867 | E70: 1.5363127e-05 | F70: Ubiquitin specific peptidase 18
A71: ENSMUSG00000096727 | B71: Psmb9 | C71: 16912 | D71: 1.7261133 | E71: 0.00010382353 | F71: Proteasome (prosome, macropain) subunit, beta type 9 (large multifunctional peptidase 2)
A72: ENSMUSG00000025017 | B72: Pik3ap1 | C72: 83490 | D72: 1.7243783 | E72: 3.2783895e-05 | F72: Phosphoinositide-3-kinase adaptor protein 1
A73: ENSMUSG00000055413 | B73: H2-Q5 | C73: 15016 | D73: 1.7240767 | E73: 1.4578969e-05 | F73: Histocompatibility 2, Q region locus 5
A74: ENSMUSG00000034116 | B74: Vav1 | C74: 22324 | D74: 1.7215517 | E74: 0.00026581407 | F74: Vav 1 oncogene
A75: ENSMUSG00000053101 | B75: Gpr141 | C75: 353346 | D75: 1.70676 | E75: 0.0034913194 | F75: G protein-coupled receptor 141
A76: ENSMUSG00000055541 | B76: Lair1 | C76: 52855 | D76: 1.7062083 | E76: 0.00066977522 | F76: Leukocyte-associated Ig-like receptor 1
A77: ENSMUSG00000040613 | B77: Apobec1 | C77: 11810 | D77: 1.6891483 | E77: 0.00023503033 | F77: Apolipoprotein B mRNA editing enzyme, catalytic polypeptide 1
A78: ENSMUSG00000060586 | B78: H2-Eb1 | C78: 14969 | D78: 1.6625683 | E78: 4.1471239e-05 | F78: Histocompatibility 2, class II antigen E beta
A79: ENSMUSG00000058715 | B79: Fcer1g | C79: 14127 | D79: 1.6541833 | E79: 0.00014399829 | F79: Fc receptor, IgE, high affinity I, gamma polypeptide
A80: ENSMUSG00000040552 | B80: C3ar1 | C80: 12267 | D80: 1.6512217 | E80: 9.4096177e-05 | F80: Complement component 3a receptor 1
... A124: ENSMUSG00000032661 | B124: Oas3 | C124: 246727 | D124: 1.3980217 | E124: 9.6215038e-05 | F124: 2'-5' oligoadenylate synthetase 3
A125: ENSMUSG00000000386 | B125: Mx1 | C125: NA | D125: 1.3964683 | E125: 0.0030428116 | F125: MX dynamin-like GTPase 1
A126: ENSMUSG00000030579 | B126: Tyrobp | C126: 22177 | D126: 1.3964333 | E126: 0.0002182558 | F126: TYRO protein tyrosine kinase binding protein
A127: ENSMUSG00000027009 | B127: Itga4 | C127: 16401 | D127: 1.389955 | E127: 0.00013853584 | F127: Integrin alpha 4
A128: ENSMUSG00000056888 | B128: Glipr1 | C128: 73690 | D128: 1.3805833 | E128: 0.00029619759 | F128: GLI pathogenesis related 1
A129: ENSMUSG00000079419 | B129: Ms4a6c | C129: 73656 | D129: 1.369515 | E129: 0.00031059865 | F129: Membrane-spanning 4-domains, subfamily A, member 6C
A130: ENSMUSG00000003882 | B130: Il7r | C130: 16197 | D130: 1.369235 | E130: 0.001827842 | F130: Interleukin 7 receptor
A131: ENSMUSG00000024164 | B131: C3 | C131: 12266 | D131: 1.36768 | E131: 0.00028951703 | F131: Complement component 3
A132: ENSMUSG00000072620 | B132: Slfn2 | C132: 20556 | D132: 1.365525 | E132: 0.00035958044 | F132: Schlafen 2
A133: ENSMUSG00000102418 | B133: Sh2d1b1 | C133: 26904 | D133: 1.36229 | E133: 0.00051469343 | F133: SH2 domain containing 1B1
A134: ENSMUSG00000049109 | B134: Themis | C134: 210757 | D134: 1.355415 | E134: 0.0061087055 | F134: Thymocyte selection associated
A135: ENSMUSG00000027863 | B135: Cd2 | C135: 12481 | D135: 1.350525 | E135: 0.00079438807 | F135: CD2 antigen
A136: ENSMUSG00000022372 | B136: Sla | C136: 20491 | D136: 1.3446667 | E136: 0.0015261007 | F136: Src-like adaptor
...

Sheet Signifiacant
B1: Ensembl_ID | C1: Regulation | D1: PBS_1 | E1: PBS_2 | F1: PBS_3 | G1: PBS_4 | H1: PBS_5 | I1: PBS_6 | J1: CVB3_1 | K1: CVB3_2 | L1: CVB3_3 | M1: CVB3_4 | N1: CVB3_5 | O1: CVB3_6 | P1: Adj P | Q1: Log2FC
A2: Ccl8 | B2: ENSMUSG00000009185 | C2: Up | D2: 4.1069 | E2: 4.15382 | F2: 4.60538 | G2: 4.58434 | H2: 4.407 | I2: 3.89722 | J2: 8.23425 | K2: 7.10983 | L2: 6.64488 | M2: 7.8129 | N2: 7.07789 | O2: 8.69405 | P2: 1.5363127e-05 | Q2: 3.30319
A3: Ccr2 | B3: ENSMUSG00000049103 | C3: Up | D3: 4.54706 | E3: 4.43309 | F3: 4.54251 | G3: 4.63288 | H3: 4.40483 | I3: 4.6258 | J3: 8.46649 | K3: 7.3524 | L3: 6.73418 | M3: 7.24528 | N3: 7.16411 | O3: 8.22634 | P3: 1.527808e-05 | Q3: 3.0004383
A4: Ccr5 | B4: ENSMUSG00000079227 | C4: Up | D4: 5.84382 | E4: 5.80229 | F4: 5.61604 | G4: 5.87411 | H4: 5.39835 | I4: 5.7727 | J4: 9.10723 | K4: 7.8835 | L4: 7.6596 | M4: 8.29752 | N4: 7.99339 | O4: 9.17817 | P4: 1.5710531e-05 | Q4: 2.63535
A5: Cxcl9 | B5: ENSMUSG00000029417 | C5: Up | D5: 5.2269 | E5: 4.78852 | F5: 5.25518 | G5: 4.63148 | H5: 4.26693 | I5: 4.55291 | J5: 8.69757 | K5: 6.85064 | L5: 6.94169 | M5: 7.44808 | N5: 6.46996 | O5: 7.79137 | P5: 0.00014746115 | Q5: 2.579565
A6: Cxcl10 | B6: ENSMUSG00000034855 | C6: Up | D6: 4.92694 | E6: 5.32775 | F6: 5.15205 | G6: 4.87457 | H6: 4.98314 | I6: 5.1733 | J6: 8.75771 | K6: 6.8792 | L6: 7.3466 | M6: 7.02591 | N6: 6.98956 | O6: 8.02694 | P6: 7.5372051e-05 | Q6: 2.4313617
A7: Ccl3 | B7: ENSMUSG00000000982 | C7: Up | D7: 5.09971 | E7: 4.86651 | F7: 5.13969 | G7: 4.81819 | H7: 4.68009 | I7: 4.7085 | J7: 7.62399 | K7: 6.33273 | L7: 6.39305 | M7: 6.62982 | N7: 6.72262 | O7: 7.52236 | P7: 6.0734935e-05 | Q7: 1.9853133
A8: Ccl12 | B8: ENSMUSG00000035352 | C8: Up | D8: 4.74162 | E8: 5.12967 | F8: 4.65005 | G8: 4.99802 | H8: 4.66667 | I8: 4.93917 | J8: 6.91111 | K8: 5.87261 | L8: 5.83887 | M8: 6.30292 | N8: 6.50017 | O8: 7.20937 | P8: 0.00026360408 | Q8: 1.584975
A9: Il2rb | B9: ENSMUSG00000068227 | C9: Up | D9: 5.28996 | E9: 5.34408 | F9: 5.05677 | G9: 5.02643 | H9: 4.86062 | I9: 5.1429 | J9: 7.36007 | K9: 6.43891 | L9: 5.91149 | M9: 6.84418 | N9: 6.01016 | O9: 6.8864 | P9: 0.00052559898 | Q9: 1.455075
A10: Il10ra | B10: ENSMUSG00000032089 | C10: Up | D10: 6.39355 | E10: 6.25381 | F10: 6.48841 | G10: 6.32342 | H10: 6.417 | I10: 6.30205 | J10: 8.20778 | K10: 7.4561 | L10: 7.14079 | M10: 7.68123 | N10: 7.2488 | O10: 8.06217 | P10: 0.00018798093 | Q10: 1.2697717
A11: Ccl7 | B11: ENSMUSG00000035373 | C11: Up | D11: 5.54686 | E11: 5.82813 | F11: 5.5871 | G11: 5.9121 | H11: 5.89787 | I11: 6.03771 | J11: 7.402 | K11: 6.36559 | L11: 6.47181 | M11: 6.54884 | N11: 7.1708 | O11: 7.98086 | P11: 0.004642207 | Q11: 1.188355
A12: Il18rap | B12: ENSMUSG00000026068 | C12: Up | D12: 4.67251 | E12: 4.97668 | F12: 4.58081 | G12: 4.69083 | H12: 4.8052 | I12: 4.74667 | J12: 6.15394 | K12: 6.01225 | L12: 5.23994 | M12: 6.29883 | N12: 5.42058 | O12: 6.3937 | P12: 0.00077213599 | Q12: 1.1744233
A13: Cxcr3 | B13: ENSMUSG00000050232 | C13: Up | D13: 5.56243 | E13: 5.73993 | F13: 5.55902 | G13: 5.61 | H13: 5.66524 | I13: 5.54055 | J13: 7.43509 | K13: 6.72082 | L13: 6.46199 | M13: 6.84274 | N13: 6.06948 | O13: 7.17076 | P13: 0.0007706494 | Q13: 1.1706183
... A15: Tnfrsf1b | B15: ENSMUSG00000028599 | C15: Up | D15: 7.43654 | E15: 7.43843 | F15: 7.5246 | G15: 7.51029 | H15: 7.51509 | I15: 7.63884 | J15: 9.14693 | K15: 8.21881 | L15: 8.11662 | M15: 8.65592 | N15: 8.10399 | O15: 9.1097 | P15: 0.0015663148 | Q15: 1.04803
