Workbook

Sheet DEG
A1: ensembl_ID | B1: symbol | C1: entrezgene_id | D1: log2FC | E1: Adjusted_P_value | F1: description
A2: ENSMUSG00000090231 | B2: Cfb | C2: 14962 | D2: 9.7162446 | E2: 1.43149981529464e-14 | F2: Complement factor B
A3: ENSMUSG00000040026 | B3: Saa3 | C3: 20210 | D3: 7.2370427 | E3: 3.89759562629108e-13 | F3: Serum amyloid A 3
A4: ENSMUSG00000025498 | B4: Irf7 | C4: 54123 | D4: 7.076085 | E4: 3.03386311824972e-15 | F4: Interferon regulatory factor 7
A5: ENSMUSG00000099974 | B5: Bcl2a1d | C5: 12047 | D5: 7.0067651 | E5: 6.26862425213091e-12 | F5: B cell leukemia/lymphoma 2 related protein A1d
A6: ENSMUSG00000034855 | B6: Cxcl10 | C6: 15945 | D6: 6.811374 | E6: 5.67575092788759e-17 | F6: C-X-C motif chemokine ligand 10
A7: ENSMUSG00000066363 | B7: Serpina3f | C7: 238393 | D7: 6.446623 | E7: 2.23541257981312e-15 | F7: Serine (or cysteine) peptidase inhibitor, clade A, member 3F
A8: ENSMUSG00000037321 | B8: Tap1 | C8: 21354 | D8: 6.3814615 | E8: 1.68965590368071e-13 | F8: Transporter 1, ATP-binding cassette, sub-family B (MDR/TAP)
A9: ENSMUSG00000029322 | B9: Plac8 | C9: 231507 | D9: 6.3566216 | E9: 1.22049891045816e-15 | F9: Placenta-specific 8
A10: ENSMUSG00000035385 | B10: Ccl2 | C10: 20296 | D10: 6.2746062 | E10: 1.32865609788276e-12 | F10: C-C motif chemokine ligand 2
A11: ENSMUSG00000041827 | B11: Oasl1 | C11: 231655 | D11: 6.2535475 | E11: 1.43149981529464e-14 | F11: 2'-5' oligoadenylate synthetase-like 1
A12: ENSMUSG00000073418 | B12: C4b | C12: 12268 | D12: 6.2292245 | E12: 9.40484433310852e-09 | F12: Complement C4B (Chido blood group)
A13: ENSMUSG00000026822 | B13: Lcn2 | C13: 16819 | D13: 6.108643 | E13: 3.54703071793803e-10 | F13: Lipocalin 2
A14: ENSMUSG00000035042 | B14: Ccl5 | C14: 20304 | D14: 5.9944097 | E14: 2.42709114783387e-10 | F14: C-C motif chemokine ligand 5
A15: ILMN_2996973 | B15: ILMN_2996973 | C15: NA | D15: 5.9265002 | E15: 4.31510297196983e-11 | F15: NA
A16: ENSMUSG00000057346 | B16: Apol9a | C16: 223672 | D16: 5.8684855 | E16: 1.43149981529464e-14 | F16: Apolipoprotein L 9a
A17: ENSMUSG00000023341 | B17: Mx2 | C17: 17858 | D17: 5.8275135 | E17: 6.03691000205596e-15 | F17: MX dynamin-like GTPase 2
A18: ENSMUSG00000074896 | B18: Ifit3 | C18: 15959 | D18: 5.6161721 | E18: 1.43149981529464e-14 | F18: Interferon-induced protein with tetratricopeptide repeats 3
A19: ENSMUSG00000066850 | B19: Vmn1r65 | C19: 81013 | D19: 5.5708633 | E19: 6.96579257300818e-14 | F19: Vomeronasal 1 receptor 65
A20: ENSMUSG00000052270 | B20: Fpr2 | C20: 14289 | D20: 5.4967663 | E20: 5.25492543014618e-11 | F20: Formyl peptide receptor 2
A21: ENSMUSG00000068246 | B21: Apol9b | C21: 71898 | D21: 5.4213172 | E21: 5.46758938178173e-15 | F21: Apolipoprotein L 9b
A22: ENSMUSG00000018930 | B22: Ccl4 | C22: 20303 | D22: 5.3961073 | E22: 6.64400970524749e-11 | F22: C-C motif chemokine ligand 4
A23: ENSMUSG00000048806 | B23: Ifnb1 | C23: 15977 | D23: 5.3801432 | E23: 1.06551060404074e-11 | F23: Interferon beta 1, fibroblast
A24: ENSMUSG00000022126 | B24: Acod1 | C24: 16365 | D24: 5.3570622 | E24: 3.67047254444179e-13 | F24: Aconitate decarboxylase 1
A25: ENSMUSG00000035373 | B25: Ccl7 | C25: 20306 | D25: 5.3452256 | E25: 1.8490216310499e-12 | F25: C-C motif chemokine ligand 7
A26: ENSMUSG00000027832 | B26: Ptx3 | C26: 19288 | D26: 5.3448173 | E26: 1.68997829082837e-11 | F26: Pentraxin related gene
A27: ENSMUSG00000035692 | B27: Isg15 | C27: 100038882 | D27: 5.3393023 | E27: 2.13254286682661e-15 | F27: ISG15 ubiquitin-like modifier
... A42: ENSMUSG00000038508 | B42: Gdf15 | C42: 23886 | D42: 4.5406153 | E42: 1.4420223786292e-08 | F42: Growth differentiation factor 15
A43: ENSMUSG00000079491 | B43: H2-T10 | C43: NA | D43: 4.4992225 | E43: 0.0019442355 | F43: Histocompatibility 2, T region locus 10
A44: ENSMUSG00000016283 | B44: H2-M2 | C44: 14990 | D44: 4.4582287 | E44: 2.27001372297031e-07 | F44: Histocompatibility 2, M region locus 2
A45: ENSMUSG00000017830 | B45: Dhx58 | C45: 80861 | D45: 4.4227189 | E45: 9.02784910543626e-13 | F45: DExH-box helicase 58
A46: ENSMUSG00000074677 | B46: Sirpb1c | C46: 100038947 | D46: 4.383109 | E46: 6.12079023199521e-10 | F46: Signal-regulatory protein beta 1C
A47: ENSMUSG00000027555 | B47: Car13 | C47: 71934 | D47: 4.381499 | E47: 1.8490216310499e-12 | F47: Carbonic anhydrase 13
A48: ENSMUSG00000027322 | B48: Siglec1 | C48: 20612 | D48: 4.338719 | E48: 2.98488849834868e-10 | F48: Sialic acid binding Ig-like lectin 1, sialoadhesin
A49: ENSMUSG00000022651 | B49: Retnlg | C49: 245195 | D49: 4.304995 | E49: 1.60825178130569e-07 | F49: Resistin like gamma
A50: ENSMUSG00000059089 | B50: Fcgr4 | C50: 246256 | D50: 4.2782187 | E50: 2.21619562041266e-09 | F50: Fc receptor, IgG, low affinity IV
A51: ENSMUSG00000029321 | B51: Slc10a6 | C51: 75750 | D51: 4.2183165 | E51: 6.67975633669514e-09 | F51: Solute carrier family 10 (sodium/bile acid cotransporter family), member 6
A52: ENSMUSG00000005667 | B52: Mthfd2 | C52: 17768 | D52: 4.1778047 | E52: 1.06551060404074e-11 | F52: Methylenetetrahydrofolate dehydrogenase (NAD+ dependent), methenyltetrahydrofolate cyclohydrolase
A53: ENSMUSG00000068245 | B53: Phf11d | C53: 219132 | D53: 4.1203029 | E53: 6.43502074240572e-15 | F53: PHD finger protein 11D
A54: ENSMUSG00000079362 | B54: Gm43302 | C54: NA | D54: 4.1086939 | E54: 3.33803267536396e-07 | F54: Predicted gene 43302
...

Sheet Viral_protein_interaction_with_
B1: Ensembl_ID | C1: Regulation | D1: PBS_1 | E1: PBS_2 | F1: PBS_3 | G1: PBS_4 | H1: PBS_5 | I1: PBS_6 | J1: PBS_7 | K1: PBS_8 | L1: PBS_9 | M1: PBS_10 | N1: PBS_11 | O1: PBS_12 | P1: CVB3_1 | Q1: CVB3_2 | R1: CVB3_3 | S1: CVB3_4 | T1: CVB3_5 | U1: CVB3_6 | V1: CVB3_7 | W1: CVB3_8 | X1: CVB3_9 | Y1: CVB3_10 | Z1: CVB3_11 | AA1: CVB3_12 | AB1: ADJ P | AC1: Log2FC
A2: Ccl3 | B2: ENSMUSG00000000982 | C2: Up | D2: 3.732863 | E2: 4.373143 | F2: 4.269202 | G2: 4.259316 | H2: 3.762054 | I2: 3.364724 | J2: 2.268454 | K2: 2.646418 | L2: 2.379925 | M2: 3.328844 | N2: 2.473692 | O2: 2.475414 | P2: 7.399428 | Q2: 6.432254 | R2: 8.221992 | S2: 9.009898 | T2: 9.419526 | U2: 9.101064 | V2: 8.327537 | W2: 8.00939 | X2: 7.838506 | Y2: 7.643233 | Z2: 8.122937 | AA2: 7.387201 | AB2: =_xlfn.XLOOKUP($A2, DEG!$B:$B, DEG!$E:$E, "not sig") -> 6.26862425213091e-12 | AC2: =IFERROR(VALUE(_xlfn.XLOOKUP($A2, DEG!$B:$B, DEG!$D:$D)), "") -> 4.7982431
A3: Ccl24 | B3: ENSMUSG00000004814 | C3: Down | D3: 5.913314 | E3: 5.948259 | F3: 5.699239 | G3: 5.852383 | H3: 6.002789 | I3: 6.265426 | J3: 5.005725 | K3: 4.895727 | L3: 5.030175 | M3: 5.325309 | N3: 5.589594 | O3: 5.487851 | P3: 4.198658 | Q3: 4.584121 | R3: 5.050869 | S3: 5.060749 | T3: 4.73127 | U3: 4.39768 | V3: 2.673225 | W3: 2.350267 | X3: 3.533083 | Y3: 3.021665 | Z3: 2.136387 | AA3: 2.799719 | AB3: =_xlfn.XLOOKUP($A3, DEG!$B:$B, DEG!$E:$E, "not sig") -> not sig | AC3: =IFERROR(VALUE(_xlfn.XLOOKUP($A3, DEG!$B:$B, DEG!$D:$D)), "")
A4: Tnfsf14 | B4: ENSMUSG00000005824 | C4: None | D4: 3.679376 | E4: 4.128335 | F4: 3.87077 | G4: 4.758094 | H4: 4.420949 | I4: 3.843362 | J4: 2.922955 | K4: 2.370583 | L4: 2.682671 | M4: 2.942575 | N4: 3.394392 | O4: 3.049856 | P4: 4.334987 | Q4: 4.237665 | R4: 4.377422 | S4: 5.41079 | T4: 4.763847 | U4: 4.622545 | V4: 3.491676 | W4: 3.506784 | X4: 3.501629 | Y4: 3.586385 | Z4: 4.209008 | AA4: 3.571683 | AB4: =_xlfn.XLOOKUP($A4, DEG!$B:$B, DEG!$E:$E, "not sig") -> not sig | AC4: =IFERROR(VALUE(_xlfn.XLOOKUP($A4, DEG!$B:$B, DEG!$D:$D)), "")
A5: Ccl8 | B5: ENSMUSG00000009185 | C5: Up | D5: 5.819288 | E5: 5.518489 | F5: 7.822567 | G5: 6.814776 | H5: 6.434487 | I5: 6.003983 | J5: 3.167085 | K5: 2.633038 | L5: 3.416162 | M5: 2.727798 | N5: 2.617947 | O5: 2.985434 | P5: 7.176524 | Q5: 8.145556 | R5: 9.165895 | S5: 8.844148 | T5: 8.562103 | U5: 8.343746 | V5: 7.246231 | W5: 7.244695 | X5: 7.421389 | Y5: 7.491553 | Z5: 7.374599 | AA5: 6.695538 | AB5: =_xlfn.XLOOKUP($A5, DEG!$B:$B, DEG!$E:$E, "not sig") -> 0.00011606699 | AC5: =IFERROR(VALUE(_xlfn.XLOOKUP($A5, DEG!$B:$B, DEG!$D:$D)), "") -> 3.1459103
A6: Csf1 | B6: ENSMUSG00000014599 | C6: None | D6: 8.681637 | E6: 8.321408 | F6: 8.601612 | G6: 9.031017 | H6: 9.669946 | I6: 9.034163 | J6: 6.979153 | K6: 7.238814 | L6: 7.041425 | M6: 7.314558 | N6: 7.400979 | O6: 7.278483 | P6: 8.847533 | Q6: 8.744782 | R6: 10.2028 | S6: 9.818203 | T6: 10.08417 | U6: 9.547471 | V6: 8.61373 | W6: 8.125376 | X6: 8.088972 | Y6: 7.977252 | Z6: 8.498712 | AA6: 8.846742 | AB6: =_xlfn.XLOOKUP($A6, DEG!$B:$B, DEG!$E:$E, "not sig") -> not sig | AC6: =IFERROR(VALUE(_xlfn.XLOOKUP($A6, DEG!$B:$B, DEG!$D:$D)), "")
A7: Il19 | B7: ENSMUSG00000016524 | C7: None | D7: 2.800978 | E7: 3.323038 | F7: 3.232015 | G7: 3.516844 | H7: 3.14621 | I7: 3.549759 | J7: 3.306976 | K7: 2.817001 | L7: 2.874075 | M7: 2.613361 | N7: 2.54826 | O7: 2.41947 | P7: 4.081946 | Q7: 3.923067 | R7: 4.219204 | S7: 3.446034 | T7: 3.076291 | U7: 3.149418 | V7: 3.017622 | W7: 2.476477 | X7: 2.497066 | Y7: 3.089725 | Z7: 2.610629 | AA7: 2.668901 | AB7: =_xlfn.XLOOKUP($A7, DEG!$B:$B, DEG!$E:$E, "not sig") -> not sig | AC7: =IFERROR(VALUE(_xlfn.XLOOKUP($A7, DEG!$B:$B, DEG!$D:$D)), "")
A8: Il10 | B8: ENSMUSG00000016529 | C8: None | D8: 3.106037 | E8: 3.800473 | F8: 3.966334 | G8: 4.260548 | H8: 4.385345 | I8: 3.793278 | J8: 1.872497 | K8: 3.139906 | L8: 1.808161 | M8: 2.343041 | N8: 2.617887 | O8: 1.869314 | P8: 4.631999 | Q8: 4.003015 | R8: 4.954117 | S8: 4.561964 | T8: 4.766564 | U8: 4.998938 | V8: 3.727938 | W8: 3.23579 | X8: 2.980503 | Y8: 3.884231 | Z8: 3.766707 | AA8: 2.867522 | AB8: =_xlfn.XLOOKUP($A8, DEG!$B:$B, DEG!$E:$E, "not sig") -> not sig | AC8: =IFERROR(VALUE(_xlfn.XLOOKUP($A8, DEG!$B:$B, DEG!$D:$D)), "")
A9: Ccl6 | B9: ENSMUSG00000018927 | C9: Up | D9: 5.652206 | E9: 5.348725 | F9: 5.888285 | G9: 6.572935 | H9: 7.073084 | I9: 6.731349 | J9: 5.668879 | K9: 4.755729 | L9: 5.640764 | M9: 6.133348 | N9: 5.107039 | O9: 5.528061 | P9: 7.965382 | Q9: 7.89488 | R9: 8.846826 | S9: 7.911948 | T9: 7.676837 | U9: 8.676037 | V9: 6.043017 | W9: 6.264644 | X9: 6.771884 | Y9: 6.78817 | Z9: 7.538805 | AA9: 6.391912 | AB9: =_xlfn.XLOOKUP($A9, DEG!$B:$B, DEG!$E:$E, "not sig") -> 0.00070304819 | AC9: =IFERROR(VALUE(_xlfn.XLOOKUP($A9, DEG!$B:$B, DEG!$D:$D)), "") -> 1.5558282
A10: Ccl4 | B10: ENSMUSG00000018930 | C10: Up | D10: 6.149229 | E10: 6.282371 | F10: 6.732971 | G10: 6.657255 | H10: 6.458295 | I10: 6.769838 | J10: 4.230562 | K10: 4.60449 | L10: 4.606245 | M10: 4.032063 | N10: 4.067749 | O10: 4.274003 | P10: 9.655231 | Q10: 8.979158 | R10: 11.12001 | S10: 11.93572 | T10: 12.2697 | U10: 11.81036 | V10: 11.0454 | W10: 10.58707 | X10: 10.5846 | Y10: 10.61493 | Z10: 10.84329 | AA10: 10.17289 | AB10: =_xlfn.XLOOKUP($A10, DEG!$B:$B, DEG!$E:$E, "not sig") -> 6.64400970524749e-11 | AC10: =IFERROR(VALUE(_xlfn.XLOOKUP($A10, DEG!$B:$B, DEG!$D:$D)), "") -> 5.3961073
A11: Ccl9 | B11: ENSMUSG00000019122 | C11: Up | D11: 8.840065 | E11: 8.995288 | F11: 9.445782 | G11: 10.25103 | H11: 10.37505 | I11: 10.09609 | J11: 9.391706 | K11: 9.092997 | L11: 9.374434 | M11: 9.608988 | N11: 8.893723 | O11: 9.14708 | P11: 10.93094 | Q11: 11.34762 | R11: 11.76468 | S11: 12.13871 | T11: 12.13535 | U11: 12.41237 | V11: 11.52151 | W11: 11.16835 | X11: 11.40698 | Y11: 11.72409 | Z11: 11.77772 | AA11: 11.03046 | AB11: =_xlfn.XLOOKUP($A11, DEG!$B:$B, DEG!$E:$E, "not sig") -> 8.20999931184665e-09 | AC11: =IFERROR(VALUE(_xlfn.XLOOKUP($A11, DEG!$B:$B, DEG!$D:$D)), "") -> 2.1538789
A12: Il20ra | B12: ENSMUSG00000020007 | C12: None | D12: 6.019115 | E12: 5.750148 | F12: 6.268509 | G12: 6.648499 | H12: 6.096996 | I12: 5.797362 | J12: 6.236621 | K12: 5.285578 | L12: 5.663755 | M12: 5.519693 | N12: 6.023644 | O12: 5.8784 | P12: 5.841314 | Q12: 6.30149 | R12: 4.936331 | S12: 5.870816 | T12: 5.767557 | U12: 5.811996 | V12: 5.24469 | W12: 4.935515 | X12: 5.018045 | Y12: 5.134768 | Z12: 5.220634 | AA12: 5.075805 | AB12: =_xlfn.XLOOKUP($A12, DEG!$B:$B, DEG!$E:$E, "not sig") -> not sig | AC12: =IFERROR(VALUE(_xlfn.XLOOKUP($A12, DEG!$B:$B, DEG!$D:$D)), "")
A13: Ccl11 | B13: ENSMUSG00000020676 | C13: Up | D13: 7.146087 | E13: 6.737074 | F13: 7.000702 | G13: 6.497556 | H13: 6.349503 | I13: 7.259057 | J13: 6.207788 | K13: 6.305795 | L13: 6.153101 | M13: 5.433076 | N13: 5.905455 | O13: 5.894673 | P13: 10.28438 | Q13: 9.674979 | R13: 10.0376 | S13: 9.293689 | T13: 9.273701 | U13: 8.844864 | V13: 7.944882 | W13: 8.779533 | X13: 8.437648 | Y13: 8.037581 | Z13: 8.966065 | AA13: 7.940924 | AB13: =_xlfn.XLOOKUP($A13, DEG!$B:$B, DEG!$E:$E, "not sig") -> 4.50941127819414e-08 | AC13: =IFERROR(VALUE(_xlfn.XLOOKUP($A13, DEG!$B:$B, DEG!$D:$D)), "") -> 2.5521649
... A80: Ccl21a | B80: ENSMUSG00000094686 | C80: None | D80: 10.04866 | E80: 9.606659 | F80: 10.73933 | G80: 10.78477 | H80: 10.8179 | I80: 10.68662 | J80: 9.871819 | K80: 10.49429 | L80: 10.2762 | M80: 10.69264 | N80: 10.10277 | O80: 10.36589 | P80: 8.456124 | Q80: 8.837795 | R80: 9.769773 | S80: 10.51399 | T80: 10.46203 | U80: 10.09297 | V80: 9.764978 | W80: 9.751976 | X80: 10.0528 | Y80: 9.533772 | Z80: 9.203368 | AA80: 8.940701 | AB80: =_xlfn.XLOOKUP($A80, DEG!$B:$B, DEG!$E:$E, "not sig") -> not sig | AC80: =IFERROR(VALUE(_xlfn.XLOOKUP($A80, DEG!$B:$B, DEG!$D:$D)), "")

Sheet Significant
B1: Ensembl_ID | C1: Regulation | D1: PBS_1 | E1: PBS_2 | F1: PBS_3 | G1: PBS_4 | H1: PBS_5 | I1: PBS_6 | J1: PBS_7 | K1: PBS_8 | L1: PBS_9 | M1: PBS_10 | N1: PBS_11 | O1: PBS_12 | P1: CVB3_1 | Q1: CVB3_2 | R1: CVB3_3 | S1: CVB3_4 | T1: CVB3_5 | U1: CVB3_6 | V1: CVB3_7 | W1: CVB3_8 | X1: CVB3_9 | Y1: CVB3_10 | Z1: CVB3_11 | AA1: CVB3_12 | AB1: Adj P | AC1: Log2FC
A2: Cxcl10 | B2: ENSMUSG00000034855 | C2: Up | D2: 3.679001 | E2: 3.55712 | F2: 3.451903 | G2: 4.636712 | H2: 5.23431 | I2: 3.837102 | J2: 3.078321 | K2: 2.81937 | L2: 4.09605 | M2: 3.629298 | N2: 3.196419 | O2: 4.362728 | P2: 9.92464 | Q2: 9.809012 | R2: 10.83386 | S2: 10.82006 | T2: 11.84433 | U2: 10.75323 | V2: 10.83389 | W2: 10.36143 | X2: 10.12786 | Y2: 10.4747 | Z2: 10.51674 | AA2: 11.01507 | AB2: 5.6757509e-17 | AC2: 6.811374
A3: Ccl2 | B3: ENSMUSG00000035385 | C3: Up | D3: 3.965974 | E3: 3.8643 | F3: 3.801343 | G3: 5.736123 | H3: 5.695053 | I3: 4.715109 | J3: 3.756465 | K3: 3.423599 | L3: 3.900927 | M3: 2.632544 | N3: 4.068484 | O3: 2.71777 | P3: 10.72473 | Q3: 7.689186 | R3: 11.31157 | S3: 10.04896 | T3: 11.43754 | U3: 10.5377 | V3: 9.315921 | W3: 9.827843 | X3: 9.825826 | Y3: 10.85627 | Z3: 10.93846 | AA3: 11.05896 | AB3: 1.3286561e-12 | AC3: 6.2746062
A4: Ccl5 | B4: ENSMUSG00000035042 | C4: Up | D4: 5.838995 | E4: 5.488177 | F4: 5.92636 | G4: 7.50128 | H4: 7.580122 | I4: 6.802401 | J4: 4.882608 | K4: 3.775749 | L4: 5.525078 | M4: 6.231719 | N4: 5.572215 | O4: 6.622128 | P4: 10.07327 | Q4: 9.554214 | R4: 9.746515 | S4: 13.28443 | T4: 13.03633 | U4: 13.12473 | V4: 13.17259 | W4: 12.91461 | X4: 12.69452 | Y4: 12.65202 | Z4: 12.46869 | AA4: 10.95783 | AB4: 2.4270911e-10 | AC4: 5.9944097
A5: Ccl4 | B5: ENSMUSG00000018930 | C5: Up | D5: 6.149229 | E5: 6.282371 | F5: 6.732971 | G5: 6.657255 | H5: 6.458295 | I5: 6.769838 | J5: 4.230562 | K5: 4.60449 | L5: 4.606245 | M5: 4.032063 | N5: 4.067749 | O5: 4.274003 | P5: 9.655231 | Q5: 8.979158 | R5: 11.12001 | S5: 11.93572 | T5: 12.2697 | U5: 11.81036 | V5: 11.0454 | W5: 10.58707 | X5: 10.5846 | Y5: 10.61493 | Z5: 10.84329 | AA5: 10.17289 | AB5: 6.6440097e-11 | AC5: 5.3961073
A6: Ccl7 | B6: ENSMUSG00000035373 | C6: Up | D6: 6.713745 | E6: 6.889841 | F6: 7.36748 | G6: 8.510201 | H6: 8.329041 | I6: 8.052849 | J6: 6.515803 | K6: 6.905987 | L6: 6.411193 | M6: 5.839233 | N6: 5.716686 | O6: 6.157954 | P6: 12.27339 | Q6: 10.28277 | R6: 13.17854 | S6: 12.52148 | T6: 13.31808 | U6: 12.76634 | V6: 11.60905 | W6: 12.01849 | X6: 12.06492 | Y6: 12.37312 | Z6: 12.55113 | AA6: 12.59541 | AB6: 1.8490216e-12 | AC6: 5.3452256
A7: Ccl3 | B7: ENSMUSG00000000982 | C7: Up | D7: 3.732863 | E7: 4.373143 | F7: 4.269202 | G7: 4.259316 | H7: 3.762054 | I7: 3.364724 | J7: 2.268454 | K7: 2.646418 | L7: 2.379925 | M7: 3.328844 | N7: 2.473692 | O7: 2.475414 | P7: 7.399428 | Q7: 6.432254 | R7: 8.221992 | S7: 9.009898 | T7: 9.419526 | U7: 9.101064 | V7: 8.327537 | W7: 8.00939 | X7: 7.838506 | Y7: 7.643233 | Z7: 8.122937 | AA7: 7.387201 | AB7: 6.2686243e-12 | AC7: 4.7982431
A8: Cxcl13 | B8: ENSMUSG00000023078 | C8: Up | D8: 8.013407 | E8: 2.986231 | F8: 2.994855 | G8: 3.65405 | H8: 5.057184 | I8: 4.79107 | J8: 2.334188 | K8: 1.884641 | L8: 1.871965 | M8: 2.459886 | N8: 2.294376 | O8: 2.194276 | P8: 7.930169 | Q8: 9.328084 | R8: 8.056357 | S8: 5.838613 | T8: 6.228478 | U8: 11.73558 | V8: 6.356177 | W8: 6.098419 | X8: 6.545989 | Y8: 6.325023 | Z8: 6.889592 | AA8: 6.344585 | AB8: 7.0613455e-05 | AC8: 3.9284114
A9: Ccl19 | B9: ENSMUSG00000071005 | C9: Up | D9: 3.962903 | E9: 4.145027 | F9: 4.920995 | G9: 6.902442 | H9: 6.685474 | I9: 6.869588 | J9: 5.198454 | K9: 4.906309 | L9: 5.131039 | M9: 5.649646 | N9: 3.676479 | O9: 4.955363 | P9: 6.012234 | Q9: 5.859959 | R9: 7.092986 | S9: 9.478674 | T9: 9.915053 | U9: 9.301248 | V9: 10.03479 | W9: 9.964456 | X9: 9.925991 | Y9: 9.794641 | Z9: 9.415395 | AA9: 8.354978 | AB9: 9.0326816e-06 | AC9: 3.5122238
A10: Cxcl1 | B10: ENSMUSG00000029380 | C10: Up | D10: 7.109701 | E10: 8.055376 | F10: 8.327415 | G10: 7.61445 | H10: 7.666294 | I10: 6.94107 | J10: 5.984258 | K10: 6.608229 | L10: 6.009306 | M10: 5.98895 | N10: 6.646306 | O10: 5.592978 | P10: 13.16141 | Q10: 10.2054 | R10: 12.68452 | S10: 11.15447 | T10: 11.52632 | U10: 10.55583 | V10: 7.802626 | W10: 8.909297 | X10: 9.184215 | Y10: 9.143141 | Z10: 9.922915 | AA10: 9.554932 | AB10: 6.0334769e-06 | AC10: 3.4383953
A11: Ccl8 | B11: ENSMUSG00000009185 | C11: Up | D11: 5.819288 | E11: 5.518489 | F11: 7.822567 | G11: 6.814776 | H11: 6.434487 | I11: 6.003983 | J11: 3.167085 | K11: 2.633038 | L11: 3.416162 | M11: 2.727798 | N11: 2.617947 | O11: 2.985434 | P11: 7.176524 | Q11: 8.145556 | R11: 9.165895 | S11: 8.844148 | T11: 8.562103 | U11: 8.343746 | V11: 7.246231 | W11: 7.244695 | X11: 7.421389 | Y11: 7.491553 | Z11: 7.374599 | AA11: 6.695538 | AB11: 0.00011606699 | AC11: 3.1459103
A12: Ccl12 | B12: ENSMUSG00000035352 | C12: Up | D12: 7.219018 | E12: 7.944047 | F12: 7.635553 | G12: 8.770044 | H12: 8.396864 | I12: 7.931365 | J12: 6.092378 | K12: 6.922506 | L12: 6.385633 | M12: 6.301167 | N12: 6.338306 | O12: 6.576971 | P12: 7.918668 | Q12: 8.916939 | R12: 10.80445 | S12: 11.19346 | T12: 11.64915 | U12: 11.34657 | V12: 10.64829 | W12: 10.33684 | X12: 10.22056 | Y12: 10.21671 | Z12: 10.14418 | AA12: 10.01796 | AB12: 5.1909525e-07 | AC12: 3.0749937
A13: Cxcl9 | B13: ENSMUSG00000029417 | C13: Up | D13: 8.161982 | E13: 8.43314 | F13: 8.128764 | G13: 9.190133 | H13: 9.731312 | I13: 9.578144 | J13: 7.863133 | K13: 8.604587 | L13: 8.181404 | M13: 8.331323 | N13: 8.115845 | O13: 8.304748 | P13: 8.57174 | Q13: 10.42906 | R13: 10.21609 | S13: 12.4393 | T13: 12.29733 | U13: 12.07158 | V13: 12.40951 | W13: 11.61987 | X13: 11.27422 | Y13: 11.39397 | Z13: 11.22957 | AA13: 10.7414 | AB13: 1.6207585e-06 | AC13: 2.6724271
... A27: Tnfsf10 | B27: ENSMUSG00000039304 | C27: Up | D27: 7.627724 | E27: 7.622294 | F27: 7.670067 | G27: 7.740807 | H27: 7.422027 | I27: 7.752008 | J27: 6.681165 | K27: 7.041954 | L27: 6.548813 | M27: 6.797221 | N27: 6.931352 | O27: 7.145818 | P27: 6.841069 | Q27: 8.529508 | R27: 8.085595 | S27: 8.444692 | T27: 8.812742 | U27: 8.466317 | V27: 8.826563 | W27: 8.225132 | X27: 7.927572 | Y27: 8.397116 | Z27: 8.183098 | AA27: 8.705424 | AB27: 0.00051391863 | AC27: 1.0386315
