Workbook

Sheet DEG
A1: ensembl_ID | B1: symbol | C1: entrezgene_id | D1: log2FC | E1: Adjusted_P_value | F1: description
A2: ENSMUSG00000000982 | B2: Ccl3 | C2: 20302 | D2: 3.7448662 | E2: 0.0097171379 | F2: C-C motif chemokine ligand 3
A3: ENSMUSG00000066363 | B3: Serpina3f | C3: 238393 | D3: 3.6868652 | E3: 0.0025065656 | F3: Serine (or cysteine) peptidase inhibitor, clade A, member 3F
A4: ENSMUSG00000078763 | B4: Slfn1 | C4: 20555 | D4: 3.5613856 | E4: 3.14160291623168e-06 | F4: Schlafen 1
A5: ENSMUSG00000015437 | B5: Gzmb | C5: 14939 | D5: 3.4281128 | E5: 0.00036202992 | F5: Granzyme B
A6: ENSMUSG00000030144 | B6: Clec4d | C6: 17474 | D6: 3.4250624 | E6: 0.0050974085 | F6: C-type lectin domain family 4, member d
A7: ENSMUSG00000027514 | B7: Zbp1 | C7: 58203 | D7: 3.3535475 | E7: 2.10237171859987e-09 | F7: Z-DNA binding protein 1
A8: ENSMUSG00000050359 | B8: Sprr1a | C8: 20753 | D8: 3.3341993 | E8: 0.00012583348 | F8: Small proline-rich protein 1A
A9: ENSMUSG00000057135 | B9: Scimp | C9: 327957 | D9: 3.3231752 | E9: 0.0005018806 | F9: SLP adaptor and CSK interacting membrane protein
A10: ENSMUSG00000041481 | B10: Serpina3g | C10: 20715 | D10: 3.2720188 | E10: 2.23276931988844e-05 | F10: Serine (or cysteine) peptidase inhibitor, clade A, member 3G
A11: ENSMUSG00000023132 | B11: Gzma | C11: 14938 | D11: 3.2398346 | E11: 1.9953915047949e-11 | F11: Granzyme A
A12: ENSMUSG00000035042 | B12: Ccl5 | C12: 20304 | D12: 3.1679378 | E12: 1.09341664899741e-17 | F12: C-C motif chemokine ligand 5
A13: ENSMUSG00000068246 | B13: Apol9b | C13: 71898 | D13: 3.1537626 | E13: 2.49160922660021e-05 | F13: Apolipoprotein L 9b
A14: ENSMUSG00000026981 | B14: Il1rn | C14: 16181 | D14: 3.0863543 | E14: 0.0040248574 | F14: Interleukin 1 receptor antagonist
A15: ENSMUSG00000029322 | B15: Plac8 | C15: 231507 | D15: 3.0643523 | E15: 5.14528244248622e-05 | F15: Placenta-specific 8
A16: ENSMUSG00000026822 | B16: Lcn2 | C16: 16819 | D16: 3.0530542 | E16: 2.47906302059266e-09 | F16: Lipocalin 2
A17: ENSMUSG00000068606 | B17: Gm4841 | C17: 225594 | D17: 3.0455927 | E17: 1.08795729939243e-05 | F17: Predicted gene 4841
A18: ENSMUSG00000000386 | B18: Mx1 | C18: NA | D18: 3.0331752 | E18: 0.001929406 | F18: MX dynamin-like GTPase 1
A19: ENSMUSG00000004612 | B19: Nkg7 | C19: 72310 | D19: 3.0200716 | E19: 4.39319998134839e-07 | F19: Natural killer cell group 7 sequence
A20: ENSMUSG00000009185 | B20: Ccl8 | C20: 20307 | D20: 3.019838 | E20: 7.75908430041051e-06 | F20: C-C motif chemokine ligand 8
A21: ENSMUSG00000037849 | B21: Ifi206 | C21: 102639543 | D21: 3.0029768 | E21: 0.0015537369 | F21: Interferon activated gene 206
A22: ENSMUSG00000074896 | B22: Ifit3 | C22: 15959 | D22: 2.9977111 | E22: 1.74976602858395e-10 | F22: Interferon-induced protein with tetratricopeptide repeats 3
A23: ENSMUSG00000090942 | B23: F830016B08Rik | C23: 240328 | D23: 2.9837175 | E23: 2.30801980364644e-06 | F23: RIKEN cDNA F830016B08 gene
A24: ENSMUSG00000035352 | B24: Ccl12 | C24: 20293 | D24: 2.9612145 | E24: 4.16603987976533e-05 | F24: C-C motif chemokine ligand 12
A25: ENSMUSG00000050370 | B25: Ch25h | C25: 12642 | D25: 2.9560535 | E25: 0.0020065939 | F25: Cholesterol 25-hydroxylase
A26: ENSMUSG00000040809 | B26: Chil3 | C26: 12655 | D26: 2.9541304 | E26: 0.00062990578 | F26: Chitinase-like 3
A27: ENSMUSG00000041827 | B27: Oasl1 | C27: 231655 | D27: 2.9423565 | E27: 2.71086579713245e-05 | F27: 2'-5' oligoadenylate synthetase-like 1
A28: ENSMUSG00000032661 | B28: Oas3 | C28: 246727 | D28: 2.9405616 | E28: 8.43523678113479e-05 | F28: 2'-5' oligoadenylate synthetase 3
A29: ENSMUSG00000050335 | B29: Lgals3 | C29: 16854 | D29: 2.8986378 | E29: 1.55974637377904e-07 | F29: Lectin, galactose binding, soluble 3
A30: ENSMUSG00000057346 | B30: Apol9a | C30: 223672 | D30: 2.8892023 | E30: 7.32253724727273e-06 | F30: Apolipoprotein L 9a
A31: ENSMUSG00000022586 | B31: Ly6i | C31: 57248 | D31: 2.8819553 | E31: 0.017169173 | F31: Lymphocyte antigen 6 family member I
A32: ENSMUSG00000030325 | B32: Klrb1c | C32: 17059 | D32: 2.8569576 | E32: 0.01209364 | F32: Killer cell lectin-like receptor subfamily B member 1C
A33: ENSMUSG00000043263 | B33: Ifi209 | C33: 236312 | D33: 2.8563323 | E33: 1.84082613471991e-05 | F33: Interferon activated gene 209
A34: ENSMUSG00000001131 | B34: Timp1 | C34: 21857 | D34: 2.8245211 | E34: 0.0004275887 | F34: Tissue inhibitor of metalloproteinase 1
A35: ENSMUSG00000015451 | B35: C4a | C35: 625018 | D35: 2.8148523 | E35: 9.467389801632e-12 | F35: Complement C4A (Rodgers blood group)
A36: ENSMUSG00000091649 | B36: Phf11b | C36: 236451 | D36: 2.7996321 | E36: 1.23364522184958e-07 | F36: PHD finger protein 11B
A37: ENSMUSG00000062488 | B37: Ifit3b | C37: 667370 | D37: 2.7945631 | E37: 9.18006303216833e-18 | F37: Interferon-induced protein with tetratricopeptide repeats 3B
A38: ENSMUSG00000024675 | B38: Ms4a4c | C38: 64380 | D38: 2.7863797 | E38: 0.004426571 | F38: Membrane-spanning 4-domains, subfamily A, member 4C
A39: ENSMUSG00000034855 | B39: Cxcl10 | C39: 15945 | D39: 2.7851598 | E39: 0.0010019743 | F39: C-X-C motif chemokine ligand 10
A40: ENSMUSG00000025498 | B40: Irf7 | C40: 54123 | D40: 2.7622341 | E40: 1.37375162927391e-42 | F40: Interferon regulatory factor 7
...

Sheet Viral_protein_interaction_with_
B1: Ensembl_ID | C1: Regulation | D1: sham_1 | E1: sham_2 | F1: sham_3 | G1: sham_4 | H1: sham_5 | I1: sham_6 | J1: CVB3_1 | K1: CVB3_2 | L1: CVB3_3 | M1: CVB3_4 | N1: CVB3_5 | O1: CVB3_6 | P1: Adj P | Q1: Log2FC
A2: Ccl3 | B2: ENSMUSG00000000982 | C2: Up | D2: 2 | E2: 2 | F2: 2 | G2: 2 | H2: 2 | I2: 2.2802159 | J2: 3.4400064 | K2: 3.1122354 | L2: 2.2545154 | M2: 2.4813727 | N2: 2.9377718 | O2: 3.8273305 | P2: =_xlfn.XLOOKUP($A2, DEG!$B:$B, DEG!$E:$E, "not sig") -> 0.0097171379 | Q2: =IFERROR(VALUE(_xlfn.XLOOKUP($A2, DEG!$B:$B, DEG!$D:$D)), "") -> 3.7448662
A3: Ccl24 | B3: ENSMUSG00000004814 | C3: None | D3: 3.7339937 | E3: 3.5033929 | F3: 3.6011703 | G3: 2.9578262 | H3: 3.4440596 | I3: 3.6524938 | J3: 2.8167483 | K3: 2.6607477 | L3: 2.4707918 | M3: 2.8416856 | N3: 2.9377718 | O3: 2.8519058 | P3: =_xlfn.XLOOKUP($A3, DEG!$B:$B, DEG!$E:$E, "not sig") -> not sig | Q3: =IFERROR(VALUE(_xlfn.XLOOKUP($A3, DEG!$B:$B, DEG!$D:$D)), "")
A4: Tnfsf14 | B4: ENSMUSG00000005824 | C4: None | D4: 2 | E4: 2.2677138 | F4: 2 | G4: 2 | H4: 2 | I4: 2 | J4: 2 | K4: 2.6607477 | L4: 2 | M4: 2.2606709 | N4: 2 | O4: 2.181608 | P4: =_xlfn.XLOOKUP($A4, DEG!$B:$B, DEG!$E:$E, "not sig") -> not sig | Q4: =IFERROR(VALUE(_xlfn.XLOOKUP($A4, DEG!$B:$B, DEG!$D:$D)), "")
A5: Ccl8 | B5: ENSMUSG00000009185 | C5: Up | D5: 2 | E5: 3.1527618 | F5: 2.293945 | G5: 3.3621248 | H5: 3.5538328 | I5: 2.5147567 | J5: 4.6622101 | K5: 5.9012668 | L5: 4.1611875 | M5: 4.4737405 | N5: 4.3817292 | O5: 6.2562469 | P5: =_xlfn.XLOOKUP($A5, DEG!$B:$B, DEG!$E:$E, "not sig") -> 7.75908430041051e-06 | Q5: =IFERROR(VALUE(_xlfn.XLOOKUP($A5, DEG!$B:$B, DEG!$D:$D)), "") -> 3.019838
A6: Csf1 | B6: ENSMUSG00000014599 | C6: None | D6: 7.0691279 | E6: 6.5120463 | F6: 6.4605392 | G6: 6.8401196 | H6: 6.6736792 | I6: 6.2155917 | J6: 6.8665601 | K6: 6.8129474 | L6: 6.4099454 | M6: 6.6069286 | N6: 6.7052342 | O6: 7.3893919 | P6: =_xlfn.XLOOKUP($A6, DEG!$B:$B, DEG!$E:$E, "not sig") -> not sig | Q6: =IFERROR(VALUE(_xlfn.XLOOKUP($A6, DEG!$B:$B, DEG!$D:$D)), "")
A7: Il19 | B7: ENSMUSG00000016524 | C7: None | D7: 2 | E7: 2.4934394 | F7: 2 | G7: 2 | H7: 2 | I7: 2 | J7: 2 | K7: 2 | L7: 2 | M7: 2 | N7: 2 | O7: 2.181608 | P7: =_xlfn.XLOOKUP($A7, DEG!$B:$B, DEG!$E:$E, "not sig") -> not sig | Q7: =IFERROR(VALUE(_xlfn.XLOOKUP($A7, DEG!$B:$B, DEG!$D:$D)), "")
A8: Ccl6 | B8: ENSMUSG00000018927 | C8: Up | D8: 7.2563911 | E8: 5.8938573 | F8: 5.9717026 | G8: 5.9495202 | H8: 5.7055333 | I8: 5.441128 | J8: 7.3633642 | K8: 7.6875774 | L8: 6.4099454 | M8: 6.7832882 | N8: 6.2849925 | O8: 7.7794489 | P8: =_xlfn.XLOOKUP($A8, DEG!$B:$B, DEG!$E:$E, "not sig") -> 0.0022044071 | Q8: =IFERROR(VALUE(_xlfn.XLOOKUP($A8, DEG!$B:$B, DEG!$D:$D)), "") -> 1.2092101
A9: Ccl4 | B9: ENSMUSG00000018930 | C9: Up | D9: 2 | E9: 2.2677138 | F9: 2.293945 | G9: 2.3941047 | H9: 2.8956339 | I9: 2 | J9: 3.7968686 | K9: 4.226214 | L9: 2.4707918 | M9: 2.9928979 | N9: 2.4501972 | O9: 4.4401177 | P9: =_xlfn.XLOOKUP($A9, DEG!$B:$B, DEG!$E:$E, "not sig") -> 0.023666898 | Q9: =IFERROR(VALUE(_xlfn.XLOOKUP($A9, DEG!$B:$B, DEG!$D:$D)), "") -> 2.6512925
A10: Ccl9 | B10: ENSMUSG00000019122 | C10: Up | D10: 4.9962842 | E10: 5.128977 | F10: 4.7815048 | G10: 4.9838225 | H10: 5.6070997 | I10: 5.0880026 | J10: 6.8284047 | K10: 7.2025069 | L10: 5.8585227 | M10: 5.4464925 | N10: 4.9244963 | O10: 7.0174971 | P10: =_xlfn.XLOOKUP($A10, DEG!$B:$B, DEG!$E:$E, "not sig") -> 0.0032548383 | Q10: =IFERROR(VALUE(_xlfn.XLOOKUP($A10, DEG!$B:$B, DEG!$D:$D)), "") -> 1.4165721
A11: Ccl11 | B11: ENSMUSG00000020676 | C11: None | D11: 2 | E11: 3.2793463 | F11: 3.236296 | G11: 4.0500733 | H11: 3.4440596 | I11: 2.8933671 | J11: 3.5378321 | K11: 4.226214 | L11: 3.1094339 | M11: 3.6682974 | N11: 3.5013805 | O11: 4.3669699 | P11: =_xlfn.XLOOKUP($A11, DEG!$B:$B, DEG!$E:$E, "not sig") -> not sig | Q11: =IFERROR(VALUE(_xlfn.XLOOKUP($A11, DEG!$B:$B, DEG!$D:$D)), "")
A12: Cxcl14 | B12: ENSMUSG00000021508 | C12: None | D12: 4.4990034 | E12: 6.2743264 | F12: 6.3042931 | G12: 6.7587584 | H12: 6.2367882 | I12: 6.312167 | J12: 6.0539233 | K12: 6.5875112 | L12: 6.0216449 | M12: 6.6530805 | N12: 7.1317174 | O12: 7.5047077 | P12: =_xlfn.XLOOKUP($A12, DEG!$B:$B, DEG!$E:$E, "not sig") -> not sig | Q12: =IFERROR(VALUE(_xlfn.XLOOKUP($A12, DEG!$B:$B, DEG!$D:$D)), "")
A13: Il6st | B13: ENSMUSG00000021756 | C13: None | D13: 7.995819 | E13: 8.1933791 | F13: 8.2093397 | G13: 8.0101903 | H13: 8.1258612 | I13: 8.2321676 | J13: 8.5174386 | K13: 8.342776 | L13: 8.3063105 | M13: 8.3540037 | N13: 8.4102239 | O13: 8.2527907 | P13: =_xlfn.XLOOKUP($A13, DEG!$B:$B, DEG!$E:$E, "not sig") -> not sig | Q13: =IFERROR(VALUE(_xlfn.XLOOKUP($A13, DEG!$B:$B, DEG!$D:$D)), "")
... A72: Ccl27b | B72: ENSMUSG00000096826 | C72: None | D72: 2 | E72: 2.6885793 | F72: 2.293945 | G72: 2.7033258 | H72: 2 | I72: 3.0509425 | J72: 2.6517508 | K72: 2.4722464 | L72: 2.2545154 | M72: 2.9928979 | N72: 2.4501972 | O72: 3.3077899 | P72: =_xlfn.XLOOKUP($A72, DEG!$B:$B, DEG!$E:$E, "not sig") -> not sig | Q72: =IFERROR(VALUE(_xlfn.XLOOKUP($A72, DEG!$B:$B, DEG!$D:$D)), "")

Sheet SigPathGenes
A1: Gene.Symbol | B1: Ensembl_ID | C1: Regulation | D1: sham_1 | E1: sham_2 | F1: sham_3 | G1: sham_4 | H1: sham_5 | I1: sham_6 | J1: CVB3_1 | K1: CVB3_2 | L1: CVB3_3 | M1: CVB3_4 | N1: CVB3_5 | O1: CVB3_6 | P1: Adj P | Q1: Log2FC
A2: Ccl3 | B2: ENSMUSG00000000982 | C2: Up | D2: 2 | E2: 2 | F2: 2 | G2: 2 | H2: 2 | I2: 2.2802159 | J2: 3.4400064 | K2: 3.1122354 | L2: 2.2545154 | M2: 2.4813727 | N2: 2.9377718 | O2: 3.8273305 | P2: 0.0097171379 | Q2: 3.7448662
A3: Ccl5 | B3: ENSMUSG00000035042 | C3: Up | D3: 4.9962842 | E3: 4.4010486 | F3: 4.4042968 | G3: 3.9362678 | H3: 4.0794981 | I3: 3.7476634 | J3: 6.6096378 | K3: 7.7037473 | L3: 6.5472309 | M3: 6.3369591 | N3: 6.4632334 | O3: 7.8142601 | P3: 1.09341664899741e-17 | Q3: 3.1679378
A4: Ccl8 | B4: ENSMUSG00000009185 | C4: Up | D4: 2 | E4: 3.1527618 | F4: 2.293945 | G4: 3.3621248 | H4: 3.5538328 | I4: 2.5147567 | J4: 4.6622101 | K4: 5.9012668 | L4: 4.1611875 | M4: 4.4737405 | N4: 4.3817292 | O4: 6.2562469 | P4: 7.75908430041051e-06 | Q4: 3.019838
A5: Ccl12 | B5: ENSMUSG00000035352 | C5: Up | D5: 3.7339937 | E5: 3.1527618 | F5: 3.3684426 | G5: 2 | H5: 3.5538328 | I5: 2.2802159 | J5: 5.286358 | K5: 5.4429873 | L5: 4.097575 | M5: 4.2517732 | N5: 4.2210325 | O5: 6.4368734 | P5: 4.16603987976533e-05 | Q5: 2.9612145
A6: Cxcl10 | B6: ENSMUSG00000034855 | C6: Up | D6: 5.365398 | E6: 4.0209388 | F6: 3.7048195 | G6: 3.677571 | H6: 3.75111 | I6: 3.3222951 | J6: 5.3947738 | K6: 7.1795657 | L6: 4.4429444 | M6: 4.9510682 | N6: 5.6480224 | O6: 7.7182712 | P6: 0.0010019743 | Q6: 2.7851598
A7: Ccl4 | B7: ENSMUSG00000018930 | C7: Up | D7: 2 | E7: 2.2677138 | F7: 2.293945 | G7: 2.3941047 | H7: 2.8956339 | I7: 2 | J7: 3.7968686 | K7: 4.226214 | L7: 2.4707918 | M7: 2.9928979 | N7: 2.4501972 | O7: 4.4401177 | P7: 0.023666898 | Q7: 2.6512925
A8: Ccl2 | B8: ENSMUSG00000035385 | C8: Up | D8: 2 | E8: 3.9465735 | F8: 3.6011703 | G8: 3.5284523 | H8: 4.6730293 | I8: 4.0757547 | J8: 6.5167183 | K8: 6.8521629 | L8: 4.3908241 | M8: 4.4213676 | N8: 4.7781311 | O8: 7.3328923 | P8: 0.0025474058 | Q8: 2.6140611
A9: Ccl7 | B9: ENSMUSG00000035373 | C9: Up | D9: 4.9962842 | E9: 4.2851276 | F9: 3.6011703 | G9: 4.0500733 | H9: 4.4639473 | I9: 3.8369417 | J9: 6.2968296 | K9: 6.7520499 | L9: 4.6785628 | M9: 5.1248893 | N9: 5.4202149 | O9: 7.3940018 | P9: 1.08753240539106e-05 | Q9: 2.385778
A10: Ccr1 | B10: ENSMUSG00000025804 | C10: Up | D10: 2 | E10: 2.2677138 | F10: 3.4894942 | G10: 2.3941047 | H10: 2 | I10: 2.7164464 | J10: 4.206893 | K10: 4.3950481 | L10: 3.1094339 | M10: 3.3697656 | N10: 2.792817 | O10: 4.6703624 | P10: 0.022750678 | Q10: 2.2636106
A11: Ccr2 | B11: ENSMUSG00000049103 | C11: Up | D11: 3.7339937 | E11: 2.8604417 | F11: 3.236296 | G11: 3.3621248 | H11: 3.9246275 | I11: 2.5147567 | J11: 4.786825 | K11: 5.0962151 | L11: 3.4522867 | M11: 3.9893337 | N11: 3.5013805 | O11: 4.6082406 | P11: 0.026339955 | Q11: 1.55636
A12: Il10ra | B12: ENSMUSG00000032089 | C12: Up | D12: 3.7339937 | E12: 3.5033929 | F12: 2.9289975 | G12: 3.8127102 | H12: 3.75111 | I12: 3.6524938 | J12: 4.9015268 | K12: 5.0293566 | L12: 3.9612618 | M12: 4.4213676 | N12: 4.3301272 | O12: 5.1777323 | P12: 0.0011910634 | Q12: 1.5053525
A13: Ccl9 | B13: ENSMUSG00000019122 | C13: Up | D13: 4.9962842 | E13: 5.128977 | F13: 4.7815048 | G13: 4.9838225 | H13: 5.6070997 | I13: 5.0880026 | J13: 6.8284047 | K13: 7.2025069 | L13: 5.8585227 | M13: 5.4464925 | N13: 4.9244963 | O13: 7.0174971 | P13: 0.0032548383 | Q13: 1.4165721
A14: Ccl6 | B14: ENSMUSG00000018927 | C14: Up | D14: 7.2563911 | E14: 5.8938573 | F14: 5.9717026 | G14: 5.9495202 | H14: 5.7055333 | I14: 5.441128 | J14: 7.3633642 | K14: 7.6875774 | L14: 6.4099454 | M14: 6.7832882 | N14: 6.2849925 | O14: 7.7794489 | P14: 0.0022044071 | Q14: 1.2092101
A15: Cxcl9 | B15: ENSMUSG00000029417 | C15: Up | D15: 6.1114752 | E15: 4.7016068 | F15: 5.0010154 | G15: 4.9253666 | H15: 4.4639473 | I15: 4.619422 | J15: 4.9378199 | K15: 6.4789544 | L15: 5.3859572 | M15: 5.1572747 | N15: 5.4924115 | O15: 7.1156561 | P15: 0.033904779 | Q15: 1.1885578
